Workbook

Sheet 📊 Dashboard
A2: ✅ UMAIR TASK LIST DASHBOARD
B5: 📋 TOTAL TASKS | E5: 🔄 IN PROGRESS | H5: ✅ COMPLETED | K5: 🔥 OVERDUE
B6: =COUNTA('📋 Task List'!C3:C998) -> 37 | E6: =COUNTIF('📋 Task List'!I3:I998,"In Progress") -> 4 | H6: =COUNTIF('📋 Task List'!I3:I998,"Completed") -> 29 | K6: =SUMPRODUCT(('📋 Task List'!G3:G998<TODAY())*('📋 Task List'!I3:I998<>"Completed")*('📋 Task List'!G3:G998<>"")) -> 5
B10: COMPLETION RATE
B11: =IFERROR(COUNTIF('📋 Task List'!I3:I998,"Completed")/COUNTA('📋 Task List'!F3:F998),0) -> 0.76315789
B13: PRIORITY BREAKDOWN
B15: Priority | D15: Count | F15: % of Total
B16: 🔴 Critical | D16: =COUNTIF('📋 Task List'!J3:J998,"Critical") -> 6 | F16: =IFERROR(D16/B6,0) -> 0.16216216
B17: 🟠 High | D17: =COUNTIF('📋 Task List'!J3:J998,"High") -> 13 | F17: =IFERROR(D17/B6,0) -> 0.35135135
B18: 🟡 Medium | D18: =COUNTIF('📋 Task List'!J3:J998,"Medium") -> 14 | F18: =IFERROR(D18/B6,0) -> 0.37837838
B19: 🟢 Low | D19: =COUNTIF('📋 Task List'!J3:J998,"Low") -> 5 | F19: =IFERROR(D19/B6,0) -> 0.13513514

Sheet 📈 Analytics
A1: 📈 TASK ANALYTICS
A3: STATUS SUMMARY
A4: Status | B4: Count | C4: Percentage
A5: Completed | B5: =COUNTIF('📋 Task List'!I3:I998,"Completed") -> 29 | C5: =IFERROR(B5/SUM(B5:B9),0) -> 0.76315789
A6: In Progress | B6: =COUNTIF('📋 Task List'!I3:I998,"In Progress") -> 4 | C6: =IFERROR(B6/SUM(B5:B9),0) -> 0.10526316
A7: Not Started | B7: =COUNTIF('📋 Task List'!I3:I998,"Not Started") -> 4 | C7: =IFERROR(B7/SUM(B5:B9),0) -> 0.10526316
A8: On Hold | B8: =COUNTIF('📋 Task List'!I3:I998,"On Hold") -> 1 | C8: =IFERROR(B8/SUM(B5:B9),0) -> 0.026315789
A9: Cancelled | B9: =COUNTIF('📋 Task List'!I3:I998,"Cancelled") -> 0 | C9: =IFERROR(B9/SUM(B5:B9),0) -> 0
A13: PRIORITY BREAKDOWN
A14: Priority | B14: Count | C14: Percentage
A15: Critical | B15: =COUNTIF('📋 Task List'!J3:J998,"Critical") -> 6 | C15: =IFERROR(B15/SUM(B15:B18),0) -> 0.15789474
A16: High | B16: =COUNTIF('📋 Task List'!J3:J998,"High") -> 13 | C16: =IFERROR(B16/SUM(B15:B18),0) -> 0.34210526
A17: Medium | B17: =COUNTIF('📋 Task List'!J3:J998,"Medium") -> 14 | C17: =IFERROR(B17/SUM(B15:B18),0) -> 0.36842105
A18: Low | B18: =COUNTIF('📋 Task List'!J3:J998,"Low") -> 5 | C18: =IFERROR(B18/SUM(B15:B18),0) -> 0.13157895

Sheet 📋 Task List
A1: 📋 TASK LIST
A2: # | B2: Task ID | C2: Task Name | D2: Description | E2: Category | F2: Assigned To | G2: Due Date | H2: Date Started | I2: Status | J2: Priority | K2: Progress % | L2: Notes
A3: 1 | B3: TSK-001 | C3: XYZ Task | D3: Test the Back Office functionality for requests initiated from the front end, including cancellations and other workflows. | E3: Testing | F3: Umair Ahmed | G3: 46066 | I3: Completed | J3: High | K3: 100
A4: 2 | B4: TSK-002 | C4: XYZ Task | D4: Conduct end-to-end testing on the front-end application, covering standard use cases, edge cases, and full functionality verification. | E4: Testing | F4: Umair Ahmed | G4: 46066 | I4: Completed | J4: High | K4: 100
A5: 3 | B5: TSK-003 | C5: XYZ Task | D5: Research compliance requirements, create a detailed BRD, and test backend logic and visibility in both pre-production and staging environments. | E5: Testing | F5: Umair Ahmed | G5: 46108 | I5: Completed | J5: High | K5: 100
A6: 4 | B6: TSK-004 | C6: XYZ Task | D6: Investigate and resolve revenue calculation issues in Stripe and fix the transaction export functionality for Finance. | E6: Finance | F6: Umair Ahmed | G6: 46092 | I6: Completed | J6: High | K6: 100
A7: 5 | B7: TSK-005 | C7: XYZ Task | D7: Provide a complete breakdown and analysis of standard and non-standard pricing models and revenue-sharing structures. | E7: Finance | F7: Umair Ahmed | G7: 46099 | I7: Completed | J7: High | K7: 100
A8: 6 | B8: TSK-006 | C8: XYZ Task | D8: Conduct UAT for the transition from Frame to Flow in the checkout process to ensure seamless functionality. | E8: Testing | F8: Umair Ahmed | G8: 46079 | I8: In Progress | J8: Medium | K8: 70 | L8: Pending on ASC
A9: 7 | B9: TSK-007 | C9: XYZ Task | D9: Review the updated business account onboarding process and provide detailed feedback for improvements. | E9: Product | F9: Umair Ahmed | G9: 46115 | I9: Completed | J9: Medium | K9: 60 | L9: Feedback prodiveded done form my side
A10: 8 | B10: TSK-008 | C10: XYZ Task | D10: Investigate the bank incident causing a 400 error, conduct root cause analysis, and document findings for resolution. | E10: Other | F10: Umair Ahmed | G10: 46104 | I10: Completed | J10: Critical | K10: 100
A11: 9 | B11: TSK-009 | C11: XYZ Task | D11: Conduct comprehensive research and competitor analysis to design and validate a tiered pricing model. | E11: Research | F11: Umair Ahmed | G11: 46124 | I11: Completed | J11: High | K11: 100
A12: 10 | B12: TSK-010 | C12: XYZ Task | D12: Research UK lenders and BNPL providers that offer Shariah-compliant financing solutions. | E12: Research | F12: Umair Ahmed | G12: 46101 | I12: Completed | J12: Medium | K12: 100
A13: 11 | B13: TSK-011 | C13: XYZ Task | D13: Create multiple concept papers outlining strategic product initiatives and future roadmap items. | E13: Documentation | F13: Umair Ahmed | G13: 46093 | I13: In Progress | J13: Low | K13: 70
A14: 12 | B14: TSK-012 | C14: XYZ Task | D14: Develop a concept paper allowing users to lock exchange rates for up to two years. | E14: Documentation | F14: Umair Ahmed | G14: 46108 | I14: Completed | J14: Low | K14: 100
A15: 13 | B15: TSK-013 | C15: XYZ Task | D15: Develop a concept for merchants or businesses to accept card payments via NFC-enabled devices. | E15: Documentation | F15: Umair Ahmed | G15: 46099 | I15: Completed | J15: Medium | K15: 100
A16: 14 | B16: TSK-014 | C16: XYZ Task | D16: Design a concept allowing businesses to pay invoices internationally with ease. | E16: Documentation | F16: Umair Ahmed | G16: 46096 | I16: Completed | J16: Medium | K16: 100
A17: 15 | B17: TSK-015 | C17: XYZ Task | D17: Create a detailed concept for introducing tiered pricing based on customer segmentation and personalization. | E17: Documentation | F17: Umair Ahmed | G17: 46139 | I17: Completed | J17: Medium | K17: 100
A18: 16 | B18: TSK-016 | C18: XYZ Task | D18: Prepare a TAM, SAM, and SOM analysis for open banking and other relevant services, dependent on data availability. | E18: Other | F18: Umair Ahmed | G18: 46101 | I18: On Hold | J18: High | K18: 20
A19: 17 | B19: TSK-017 | C19: XYZ Task | D19: Create a complete BRD and prototype for the business account dashboard, including feature requirements and UX flows. | E19: Product | F19: Umair Ahmed | G19: 46097 | I19: Completed | J19: Critical | K19: 100
A20: 18 | B20: TSK-018 | C20: XYZ Task | D20: Draft a comprehensive paper summarizing goals, priorities, and initiatives for Q1 to share with the PMO. | E20: Documentation | F20: Umair Ahmed | G20: 46108 | I20: Completed | J20: Medium | K20: 100
A21: 19 | B21: TSK-019 | C21: XYZ Task | D21: Develop a document outlining the enable/disable functionality of individual features per user. | E21: Documentation | F21: Umair Ahmed | G21: 46092 | I21: Completed | J21: Critical | K21: 100
... A33: 31 | B33: TSK-031 | C33: XYZ Task | D33: Conduct R&D on Stripe card issuing, including reviewing official documentation and best practices. | E33: Research | F33: Umair Ahmed | G33: 46140 | I33: In Progress | J33: High | K33: 10
A34: 32 | B34: TSK-032 | C34: XYZ Task | D34: Conduct a detailed gap analysis of existing EMI products, linked to business account ideation, identifying missing features, compliance gaps, and improvement opportunities. | E34: Research | F34: Umair Ahmed | G34: N/A | I34: Not Started | J34: Low | K34: 0
A35: 33 | B35: TSK-033 | C35: XYZ Task | D35: Map all MVP events, documenting both basic flows and feature-specific workflows to ensure complete end-to-end coverage. | E35: Other | F35: Umair Ahmed | G35: N/A | I35: Not Started | J35: Low | K35: 0
A36: 34 | B36: TSK-034 | C36: XYZ Task | D36: Conduct sessions with the Operations team to help them understand and navigate the Stripe dashboard effectively. | E36: Product | F36: Umair Ahmed | G36: 46140 | I36: Completed | J36: Medium | K36: 100
A37: 35 | B37: TSK-035 | C37: XYZ Task | D37: Research and clarify responsibility and processes when a connected account balance goes negative. | E37: Finance | F37: Umair Ahmed | G37: 46140 | I37: Completed | J37: Medium | K37: 100
A38: 36 | B38: TSK-036 | C38: XYZ Task | D38: Perform testing of Stripe functionalities in the live production environment. | E38: Product | F38: Umair Ahmed | G38: 46140 | I38: Completed | J38: Critical | K38: 100
A39: 37 | B39: TSK-037 | C39: XYZ Task | D39: Verify that all emails and notifications are correctly triggered and received in the production environment. | E39: Product | F39: Umair Ahmed | I39: Not Started | J39: High | K39: 0
A40: 38 | B40: TSK-038 | E40: Product | F40: Umair Ahmed | I40: Not Started | J40: High | K40: 0
A41: 39 | B41: TSK-039
A42: 40 | B42: TSK-040
A43: 41 | B43: TSK-041
A44: 42 | B44: TSK-042
A45: 43 | B45: TSK-043
A46: 44 | B46: TSK-044
A47: 45 | B47: TSK-045
A48: 46 | B48: TSK-046
A49: 47 | B49: TSK-047
A50: 48 | B50: TSK-048
A51: 49 | B51: TSK-049
...
